2021-06-16 10:44:54,384 ERROR: Exception on /index [GET] [in d:\python\flaskblog\env\lib\site-packages\flask\app.py:1892]
Traceback (most recent call last):
  File "d:\python\flaskblog\env\lib\site-packages\flask\app.py", line 2447, in wsgi_app
    response = self.full_dispatch_request()
  File "d:\python\flaskblog\env\lib\site-packages\flask\app.py", line 1952, in full_dispatch_request
    rv = self.handle_user_exception(e)
  File "d:\python\flaskblog\env\lib\site-packages\flask\app.py", line 1821, in handle_user_exception
    reraise(exc_type, exc_value, tb)
  File "d:\python\flaskblog\env\lib\site-packages\flask\_compat.py", line 39, in reraise
    raise value
  File "d:\python\flaskblog\env\lib\site-packages\flask\app.py", line 1950, in full_dispatch_request
    rv = self.dispatch_request()
  File "d:\python\flaskblog\env\lib\site-packages\flask\app.py", line 1936, in dispatch_request
    return self.view_functions[rule.endpoint](**req.view_args)
  File "d:\python\flaskblog\env\lib\site-packages\flask_login\utils.py", line 272, in decorated_view
    return func(*args, **kwargs)
  File "D:\Python\FlaskBlog\app\main\routes.py", line 47, in index
    prev_url=prev_url)
  File "d:\python\flaskblog\env\lib\site-packages\flask\templating.py", line 140, in render_template
    ctx.app,
  File "d:\python\flaskblog\env\lib\site-packages\flask\templating.py", line 120, in _render
    rv = template.render(context)
  File "d:\python\flaskblog\env\lib\site-packages\jinja2\environment.py", line 1090, in render
    self.environment.handle_exception()
  File "d:\python\flaskblog\env\lib\site-packages\jinja2\environment.py", line 832, in handle_exception
    reraise(*rewrite_traceback_stack(source=source))
  File "d:\python\flaskblog\env\lib\site-packages\jinja2\_compat.py", line 28, in reraise
    raise value.with_traceback(tb)
  File "D:\Python\FlaskBlog\app\templates\index.html", line 2, in top-level template code
    {% import 'bootstrap/wtf.html' as wtf %}
  File "D:\Python\FlaskBlog\app\templates\base.html", line 1, in top-level template code
    {% extends 'bootstrap/base.html' %}
  File "d:\python\flaskblog\env\lib\site-packages\flask_bootstrap\templates\bootstrap\base.html", line 1, in top-level template code
    {% block doc -%}
  File "d:\python\flaskblog\env\lib\site-packages\flask_bootstrap\templates\bootstrap\base.html", line 4, in block "doc"
    {%- block html %}
  File "d:\python\flaskblog\env\lib\site-packages\flask_bootstrap\templates\bootstrap\base.html", line 20, in block "html"
    {% block body -%}
  File "d:\python\flaskblog\env\lib\site-packages\flask_bootstrap\templates\bootstrap\base.html", line 23, in block "body"
    {% block content -%}
  File "D:\Python\FlaskBlog\app\templates\base.html", line 57, in block "content"
    {% block app_content %}{% endblock %}
  File "D:\Python\FlaskBlog\app\templates\index.html", line 11, in block "app_content"
    {% include '_post.html' %}
  File "D:\Python\FlaskBlog\app\templates\_post.html", line 4, in top-level template code
    <a href="{{ url_for('user', username=post.author.username) }}">
  File "d:\python\flaskblog\env\lib\site-packages\flask\helpers.py", line 370, in url_for
    return appctx.app.handle_url_build_error(error, endpoint, values)
  File "d:\python\flaskblog\env\lib\site-packages\flask\app.py", line 2216, in handle_url_build_error
    reraise(exc_type, exc_value, tb)
  File "d:\python\flaskblog\env\lib\site-packages\flask\_compat.py", line 39, in reraise
    raise value
  File "d:\python\flaskblog\env\lib\site-packages\flask\helpers.py", line 358, in url_for
    endpoint, values, method=method, force_external=external
  File "d:\python\flaskblog\env\lib\site-packages\werkzeug\routing.py", line 2179, in build
    raise BuildError(endpoint, values, method, self)
werkzeug.routing.BuildError: Could not build url for endpoint 'user' with values ['username']. Did you mean 'main.user' instead?
2021-06-16 10:45:49,343 ERROR: Exception on /index [GET] [in d:\python\flaskblog\env\lib\site-packages\flask\app.py:1892]
Traceback (most recent call last):
  File "d:\python\flaskblog\env\lib\site-packages\flask\app.py", line 2447, in wsgi_app
    response = self.full_dispatch_request()
  File "d:\python\flaskblog\env\lib\site-packages\flask\app.py", line 1952, in full_dispatch_request
    rv = self.handle_user_exception(e)
  File "d:\python\flaskblog\env\lib\site-packages\flask\app.py", line 1821, in handle_user_exception
    reraise(exc_type, exc_value, tb)
  File "d:\python\flaskblog\env\lib\site-packages\flask\_compat.py", line 39, in reraise
    raise value
  File "d:\python\flaskblog\env\lib\site-packages\flask\app.py", line 1950, in full_dispatch_request
    rv = self.dispatch_request()
  File "d:\python\flaskblog\env\lib\site-packages\flask\app.py", line 1936, in dispatch_request
    return self.view_functions[rule.endpoint](**req.view_args)
  File "d:\python\flaskblog\env\lib\site-packages\flask_login\utils.py", line 272, in decorated_view
    return func(*args, **kwargs)
  File "D:\Python\FlaskBlog\app\main\routes.py", line 47, in index
    prev_url=prev_url)
  File "d:\python\flaskblog\env\lib\site-packages\flask\templating.py", line 140, in render_template
    ctx.app,
  File "d:\python\flaskblog\env\lib\site-packages\flask\templating.py", line 120, in _render
    rv = template.render(context)
  File "d:\python\flaskblog\env\lib\site-packages\jinja2\environment.py", line 1090, in render
    self.environment.handle_exception()
  File "d:\python\flaskblog\env\lib\site-packages\jinja2\environment.py", line 832, in handle_exception
    reraise(*rewrite_traceback_stack(source=source))
  File "d:\python\flaskblog\env\lib\site-packages\jinja2\_compat.py", line 28, in reraise
    raise value.with_traceback(tb)
  File "D:\Python\FlaskBlog\app\templates\index.html", line 2, in top-level template code
    {% import 'bootstrap/wtf.html' as wtf %}
  File "D:\Python\FlaskBlog\app\templates\base.html", line 1, in top-level template code
    {% extends 'bootstrap/base.html' %}
  File "d:\python\flaskblog\env\lib\site-packages\flask_bootstrap\templates\bootstrap\base.html", line 1, in top-level template code
    {% block doc -%}
  File "d:\python\flaskblog\env\lib\site-packages\flask_bootstrap\templates\bootstrap\base.html", line 4, in block "doc"
    {%- block html %}
  File "d:\python\flaskblog\env\lib\site-packages\flask_bootstrap\templates\bootstrap\base.html", line 20, in block "html"
    {% block body -%}
  File "d:\python\flaskblog\env\lib\site-packages\flask_bootstrap\templates\bootstrap\base.html", line 23, in block "body"
    {% block content -%}
  File "D:\Python\FlaskBlog\app\templates\base.html", line 57, in block "content"
    {% block app_content %}{% endblock %}
  File "D:\Python\FlaskBlog\app\templates\index.html", line 11, in block "app_content"
    {% include '_post.html' %}
  File "D:\Python\FlaskBlog\app\templates\_post.html", line 4, in top-level template code
    <a href="{{ url_for('user', username=post.author.username) }}">
  File "d:\python\flaskblog\env\lib\site-packages\flask\helpers.py", line 370, in url_for
    return appctx.app.handle_url_build_error(error, endpoint, values)
  File "d:\python\flaskblog\env\lib\site-packages\flask\app.py", line 2216, in handle_url_build_error
    reraise(exc_type, exc_value, tb)
  File "d:\python\flaskblog\env\lib\site-packages\flask\_compat.py", line 39, in reraise
    raise value
  File "d:\python\flaskblog\env\lib\site-packages\flask\helpers.py", line 358, in url_for
    endpoint, values, method=method, force_external=external
  File "d:\python\flaskblog\env\lib\site-packages\werkzeug\routing.py", line 2179, in build
    raise BuildError(endpoint, values, method, self)
werkzeug.routing.BuildError: Could not build url for endpoint 'user' with values ['username']. Did you mean 'main.user' instead?
